package chap08;

public class A06_ExceptionEx6 {

	public static void main(String[] args) {
		// TODO Auto-generated method stub
        System.out.println(1);
        System.out.println(2);
        try {
        	System.out.println(3);
        	System.out.println(0/0);
        	System.out.println(4); //실행되지 않는다.
        }catch(Exception e) { //ArithmeticException 대신 Exception을 사용
        	System.out.println(5); 
        }//try-catch의 끝
        System.out.println(6);
} //main메서드의 끝
}

/*
실행 결과 
1
2
3
5
6
예제 8-5를 변경한 것인데 결과는 같다.
catch 블럭의 괄호()에 ArithmeticException 타입의 참조변수 대신에 Exception 클래스의 참조변수를 선언하였다.

ArithmeticException 클래스는 Exception 클래스의 자손
*/